<?xml version="1.0"?>
<robot name="roscontrol" xmlns:xacro="http://ros.org/wiki/xacro">

    <xacro:property name="WheelSep" value="0.46"/>
    <xacro:property name="WheelRad" value="0.1"/>
    <xacro:property name="WheelLen" value="0.05"/>
    <xacro:property name="WheelPoss" value="0.15"/>
    <xacro:property name="WheelPossZ" value="-0.05"/>

    <xacro:macro name="default_inertial" params="mass">
        <inertial>
            <mass value="${mass}" />
            <inertia ixx="1.0" ixy="0.0" ixz="0.0" iyy="1.0" iyz="0.0" izz="1.0" />
        </inertial>
    </xacro:macro>

    <link name="base_link">
        <pose>0 0 0.1 0 0 0</pose>
        <visual>
            <geometry>
                <box size="0.8 0.4 0.2"/>
            </geometry>
        </visual>
        <collision>
            <geometry>
                <box size="0.8 0.4 0.2"/>
            </geometry>
        </collision>
        <xacro:default_inertial mass="15"/>
    </link>
    <gazebo reference="base_link">
        <material>Gazebo/Blue</material>
    </gazebo>

    <!-- wheels -->
    <xacro:macro name="wheels" params = "prefex reflect">
        <!-- back wheels -->
        <link name="${prefex}_back_wheel">
            <visual>
                <origin xyz="0 0 0" rpy="0 1.5707 1.5707"/>
                <geometry>
                    <cylinder length="${WheelLen}" radius="${WheelRad}"/>
                </geometry>
            </visual>
            <collision>
                <origin xyz="0 0 0" rpy="0 1.5707 1.5707"/>
                <geometry>
                    <cylinder length="${WheelLen}" radius="${WheelRad}"/>
                </geometry>
            </collision>
            <xacro:default_inertial mass="5"/>
        </link>
        <joint name="${prefex}_back_wheel_joint" type="continuous">
            <axis xyz="0 1 0" rpy="0 0 0" />
            <parent link="base_link"/>
            <child link="${prefex}_back_wheel"/>
            <origin rpy="0 0 0" xyz="-${WheelPoss*2} ${reflect*WheelSep/2} ${WheelPossZ}"/>
            <limit effort="10000" velocity="1000"/>
            <dynamics damping="1.0" friction="1.0"/>
        </joint>
        <gazebo reference="${prefex}_back_wheel">
            <material>Gazebo/Black</material>
        </gazebo>
        <link name="${prefex}_column_back">
            <visual>
                <geometry>
                    <box size="0.01 0.04 0.02"/>
                </geometry>
            </visual>
            <collision>
                <geometry>
                    <box size="0.01 0.04 0.02"/>
                </geometry>
            </collision>
            <xacro:default_inertial mass="0.01"/>
        </link>
        <joint name="${prefex}_back_wheel_coll_joint" type="fixed">
            <child link="${prefex}_column_back"/>
            <parent link="${prefex}_back_wheel"/>
            <origin rpy="0 0 0" xyz="0.06 ${reflect*0.01} 0"/>
        </joint>
        <gazebo reference="${prefex}_column_back">
            <material>Gazebo/White</material>
        </gazebo>

        <!-- middle wheels -->
        <link name="${prefex}_middle_wheel">
            <visual>
                <origin xyz="0 0 0" rpy="0 1.5707 1.5707"/>
                <geometry>
                    <cylinder length="${WheelLen}" radius="${WheelRad}"/>
                </geometry>
            </visual>
            <collision>
                <origin xyz="0 0 0" rpy="0 1.5707 1.5707"/>
                <geometry>
                    <cylinder length="${WheelLen}" radius="${WheelRad}"/>
                </geometry>
            </collision>
            <xacro:default_inertial mass="5"/>
        </link>
        <joint name="${prefex}_middle_wheel_joint" type="continuous">
            <axis xyz="0 1 0" rpy="0 0 0" />
            <parent link="base_link"/>
            <child link="${prefex}_middle_wheel"/>
            <origin rpy="0 0 0" xyz="0 ${reflect*WheelSep/2} ${WheelPossZ}"/>
            <limit effort="10000" velocity="1000"/>
            <dynamics damping="1.0" friction="1.0"/>
        </joint>
        <gazebo reference="${prefex}_middle_wheel">
            <material>Gazebo/Black</material>
        </gazebo>
        <link name="${prefex}_column_middle">
            <visual>
                <geometry>
                    <box size="0.01 0.04 0.02"/>
                </geometry>
            </visual>
            <collision>
                <geometry>
                    <box size="0.01 0.04 0.02"/>
                </geometry>
            </collision>
            <xacro:default_inertial mass="0.01"/>
        </link>
        <joint name="${prefex}_middle_wheel_coll_joint" type="fixed">
            <child link="${prefex}_column_middle"/>
            <parent link="${prefex}_middle_wheel"/>
            <origin rpy="0 0 0" xyz="0.06 ${reflect*0.01} 0"/>
        </joint>
        <gazebo reference="${prefex}_column_middle">
            <material>Gazebo/White</material>
        </gazebo>

        <!-- front wheels -->
        <link name="${prefex}_front_wheel">
            <visual>
                <origin xyz="0 0 0" rpy="0 1.5707 1.5707"/>
                <geometry>
                    <cylinder length="${WheelLen}" radius="${WheelRad}"/>
                </geometry>
            </visual>
            <collision>
                <origin xyz="0 0 0" rpy="0 1.5707 1.5707"/>
                <geometry>
                    <cylinder length="${WheelLen}" radius="${WheelRad}"/>
                </geometry>
            </collision>
            <xacro:default_inertial mass="5"/>
        </link>
        <joint name="${prefex}_front_wheel_joint" type="continuous">
            <axis xyz="0 1 0" rpy="0 0 0" />
            <parent link="base_link"/>
            <child link="${prefex}_front_wheel"/>
            <origin rpy="0 0 0" xyz="${WheelPoss*2} ${reflect*WheelSep/2} ${WheelPossZ}"/>
            <limit effort="10000" velocity="1000"/>
            <dynamics damping="1.0" friction="1.0"/>
        </joint>
        <gazebo reference="${prefex}_front_wheel">
            <material>Gazebo/Black</material>
        </gazebo>
        <link name="${prefex}_column_front">
            <visual>
                <geometry>
                    <box size="0.01 0.04 0.02"/>
                </geometry>
            </visual>
            <collision>
                <geometry>
                    <box size="0.01 0.04 0.02"/>
                </geometry>
            </collision>
            <xacro:default_inertial mass="0.01"/>
        </link>
        <joint name="${prefex}_front_wheel_coll_joint" type="fixed">
            <child link="${prefex}_column_front"/>
            <parent link="${prefex}_front_wheel"/>
            <origin rpy="0 0 0" xyz="0.06 ${reflect*0.01} 0"/>
        </joint>
        <gazebo reference="${prefex}_column_front">
            <material>Gazebo/White</material>
        </gazebo>
    </xacro:macro>

    <xacro:wheels prefex = "right" reflect = "-1"/>
    <xacro:wheels prefex = "left" reflect = "1"/>

    <!-- Gazebo plugin for ROS Control -->
    <gazebo>
        <plugin name="gazebo_ros_control" filename="libgazebo_ros_control.so">
            <robotNamespace>/</robotNamespace>
        </plugin>
    </gazebo>
    <gazebo>
        <plugin name="differential_drive_controller" filename="libgazebo_ros_diff_drive_multiwheel.so">

            <updateRate>50</updateRate>
            <leftJoints>left_back_wheel_joint left_middle_wheel_joint left_front_wheel_joint</leftJoints>
            <rightJoints>right_back_wheel_joint right_middle_wheel_joint right_front_wheel_joint</rightJoints>
            <wheelSeparation>${WheelSep}</wheelSeparation>
            <wheelDiameter>${WheelRad*2}</wheelDiameter>
            <wheelAcceleration>0.2</wheelAcceleration>
            <wheelTorque>5</wheelTorque>
            <commandTopic>diff_drive_controller/cmd_vel</commandTopic>
            <odometryTopic>odom</odometryTopic>
            <odometryFrame>odom</odometryFrame>
            <robotBaseFrame>base_link</robotBaseFrame>
            <odometrySource>1</odometrySource>
            <publishWheelTF>true</publishWheelTF>
            <publishOdomTF>true</publishOdomTF>
            <publishWheelJointState>true</publishWheelJointState>
            <legacyMode>false</legacyMode>
        </plugin>
    </gazebo>
</robot>