<?xml version='1.0'?>

<robot name="twoWheelsRobot" xmlns:xacro="http://www.ros.org/wiki/xacro">

  <link name='base_link'>
    <pose>0 0 0.1 0 0 0</pose>

    <inertial>
      <mass value="15.0"/>
      <origin xyz="0.0 0 0" rpy=" 0 0 0"/>
      <inertia
          ixx="0.1" ixy="0" ixz="0"
          iyy="0.1" iyz="0"
          izz="0.1"
      />
    </inertial>

    <collision name='collision'>
      <origin xyz="0 0 0" rpy=" 0 0 0"/> 
      <geometry>
        <box size=".4 .2 .1"/>
      </geometry>
    </collision>

    <visual name='base_link_visual'>
      <origin xyz="0 0 0" rpy=" 0 0 0"/>
      <geometry>
        <box size=".4 .2 .1"/>
      </geometry>
    </visual>


    <collision name='back_caster_collision'>
      <origin xyz="-0.15 0 -0.05" rpy=" 0 0 0"/>
      <geometry>
        <sphere radius="0.0499"/>
      </geometry>
    </collision>

    <visual name='back_caster_visual'>
      <origin xyz="-0.15 0 -0.05" rpy=" 0 0 0"/>
      <geometry>
        <sphere radius="0.05"/>
      </geometry>
    </visual>

    <collision name='front_caster_collision'>
      <origin xyz="0.15 0 -0.05" rpy=" 0 0 0"/>
      <geometry>
        <sphere radius="0.0499"/>
      </geometry>
    </collision>

    <visual name='front_caster_visual'>
      <origin xyz="0.15 0 -0.05" rpy=" 0 0 0"/>
      <geometry>
        <sphere radius="0.05"/>
      </geometry>
    </visual>

  </link>

  <joint type="continuous" name="left_wheel_hinge">
    <origin xyz="0 0.15 0" rpy="0 0 0"/>
    <child link="left_wheel"/>
    <parent link="base_link"/>
    <axis xyz="0 1 0" rpy="0 0 0"/>
    <limit effort="10000" velocity="1000"/>
    <dynamics damping="1.0" friction="1.0"/>
  </joint>

  <link name='left_wheel'>
    <collision name='left_wheel_collision'>
      <origin xyz="0 0 0" rpy="0 1.5707 1.5707"/>
      <geometry>
        <cylinder radius="0.1" length="0.05"/>
      </geometry>
    </collision>

    <visual name='left_wheel_visual'>
      <origin xyz="0 0 0" rpy="0 1.5707 1.5707"/>
      <geometry>
        <cylinder radius="0.1" length="0.05"/>
      </geometry>
    </visual>

    <inertial>
      <mass value="5.0"/>
      <origin xyz="0.0 0 0" rpy=" 0 0 0"/>
      <inertia
          ixx="0.1" ixy="0" ixz="0"
          iyy="0.1" iyz="0"
          izz="0.1"
      />
    </inertial>
  </link>

  <joint type="continuous" name="right_wheel_hinge">
    <origin xyz="0 -0.15 0" rpy="0 0 0"/>
    <child link="right_wheel"/>
    <parent link="base_link"/>
    <axis xyz="0 1 0" rpy="0 0 0"/>
    <limit effort="10000" velocity="1000"/>
    <dynamics damping="1.0" friction="1.0"/>
  </joint>

  <link name='right_wheel'>
    <collision name='right_wheel_collision'>
      <origin xyz="0 0 0" rpy="0 1.5707 1.5707"/>
      <geometry>
        <cylinder radius="0.1" length="0.05"/>
      </geometry>
    </collision>

    <visual name='right_wheel_visual'>
      <origin xyz="0 0 0" rpy="0 1.5707 1.5707"/>
      <geometry>
        <cylinder radius="0.1" length="0.05"/>
      </geometry>
    </visual>

    <inertial>
      <mass value="5.0"/>
      <origin xyz="0.0 0 0" rpy=" 0 0 0"/>
      <inertia
          ixx="0.1" ixy="0" ixz="0"
          iyy="0.1" iyz="0"
          izz="0.1"
      />
    </inertial>
  </link>

  <gazebo reference="left_wheel">
    <material>Gazebo/Black</material>
  </gazebo>
  <gazebo reference="right_wheel">
    <material>Gazebo/Black</material>
  </gazebo>
  <gazebo reference="base_link">
    <material>Gazebo/Blue</material>
  </gazebo>


  <gazebo>
    <plugin name="differential_drive_controller" filename="libgazebo_ros_diff_drive_multiwheel.so">
      <updateRate>50</updateRate>
      <leftJoints>left_wheel_hinge</leftJoints>
      <rightJoints>right_wheel_hinge</rightJoints>
      <wheelSeparation>0.4</wheelSeparation>
      <wheelDiameter>0.2</wheelDiameter>
      <wheelAcceleration>0.2</wheelAcceleration>
      <wheelTorque>5</wheelTorque>
      <commandTopic>diff_drive_controller/cmd_vel</commandTopic>
      <odometryTopic>odom</odometryTopic>
      <odometryFrame>odom</odometryFrame>
      <robotBaseFrame>base_link</robotBaseFrame>
      <odometrySource>1</odometrySource>
      <publishWheelTF>true</publishWheelTF>
      <publishOdomTF>true</publishOdomTF>
      <publishWheelJointState>true</publishWheelJointState>
      <legacyMode>false</legacyMode>
    </plugin>
  </gazebo>

</robot>
